## 예외 처리하기

예외처리를 위한 try, catch문의 기본 구조

```
try {
    ...
} catch(예외1) {
    ...
} catch(예외2) {
    ...
}
```

ex:

```
int c;
try {
    c = 4 / 0;
} catch(ArithmeticException e) {
    c = -1;  // 예외가 발생하여 이 문장이 수행된다.
}
```

ㅤ
ㅤ

ㅤ

ㅤ

ㅤ

ㅤ

## 1. finally

```java
public class Sample {
    public void shouldBeRun() {
        System.out.println("ok thanks.");
    }

    public static void main(String[] args) {
        Sample sample = new Sample();
        int c;
        try {
            c = 4 / 0;
            sample.shouldBeRun();  // 이 코드는 실행되지 않는다.
        } catch (ArithmeticException e) {
            c = -1;
        }
    }
}
```

4/0에 의해 `ArithmeticException`이 발생하여 catch구문으로 넘어가기 때문에 `sample.shouldBeRun()`코드는 절대로 실행될 수 없을 것.

ㅤ

ㅤ

### finally를 사용한 예제

ex:

```java
public class Sample {
    public void shouldBeRun() {
        System.out.println("ok thanks.");
    }

    public static void main(String[] args) {
        Sample sample = new Sample();
        int c;
        try {
            c = 4 / 0;
        } catch (ArithmeticException e) {
            c = -1;
        } finally {
            sample.shouldBeRun();  // 예외에 상관없이 무조건 수행된다.
        }
    }
}
```

`sample.shouldBeRun()` 메서드가 수행되어 "ok, thanks" 문장이 출력될 것.

ㅤ
ㅤ

ㅤ

ㅤ

ㅤ

ㅤ

## 2. RuntimeExeption과 Exception

```java
class FoolException extends RuntimeException {
}
```

```java
class FoolException extends RuntimeException {
}

public class Sample {
    public void sayNick(String nick) {
        if("fool".equals(nick)) {
            throw new FoolException();
        }
        System.out.println("당신의 별명은 "+nick+" 입니다.");
    }

    public static void main(String[] args) {
        Sample sample = new Sample();
        sample.sayNick("fool");
        sample.sayNick("genious");
    }
}
```

실행결과

```
Exception in thread "main" FoolException
    at Sample.sayNick(Sample.java:7)
    at Sample.main(Sample.java:14)
```

`RuntimeException`은 실행시 발생하는 예외이고 `Exception`은 컴파일시 발생하는 예외이다.  
즉, `Exception`은 프로그램 작성시 이미 예측가능한 예외를 작성할 때 사용하고 `RuntimeException`은 발생 할수도 발생 안 할수도 있는 경우에 작성한다.

그래서 `Exception`을 `Checked Exception, RuntimeException을 Unchecked Exception `이라고도 한다.

ㅤ
ㅤ

ㅤ

ㅤ

ㅤ

ㅤ

## 3. Exception

```java
class FoolException extends Exception {
}
```

이렇게 하면 Sample 클래스에서 컴파일 오류가 발생할 것이다. 예측 가능한 Checked Exception이기 때문에 예외처리를 컴파일러가 강제하기 때문이다.

아래와 같이 변경하자.

```java
class FoolException extends Exception {
}

public class Sample {
    public void sayNick(String nick) {
        try {
            if("fool".equals(nick)) {
                throw new FoolException();
            }
            System.out.println("당신의 별명은 "+nick+" 입니다.");
        }catch(FoolException e) {
            System.err.println("FoolException이 발생했습니다.");
        }
    }

    public static void main(String[] args) {
        Sample sample = new Sample();
        sample.sayNick("fool");
        sample.sayNick("genious");
    }
}
```

컴파일 오류를 막기 위해 `sayNick 메서드`에서 `try... catch 문`으로 `FoolException`을 처리해야 한다.

ㅤ
ㅤ

ㅤ

ㅤ

ㅤ

ㅤ

## 4. 예외 던지기 (throws)

```java
class FoolException extends Exception {
}

public class Sample {
    public void sayNick(String nick) throws FoolException {
        if("fool".equals(nick)) {
            throw new FoolException();
        }
        System.out.println("당신의 별명은 "+nick+" 입니다.");
    }

    public static void main(String[] args) {
        Sample sample = new Sample();
        try {
            sample.sayNick("fool");
            sample.sayNick("genious");
        } catch (FoolException e) {
            System.err.println("FoolException이 발생했습니다.");
        }
    }
}
```

sayNick 메서드에서 예외를 처리하는 경우에는 다음의 두 문장이 모두 수행이된다.

```java
sample.sayNick("fool");
sample.sayNick("genious");
```

sample.sayNick("fool"); 문장 수행 시에는 FoolException이 발생하겠지만 그 다음 문장인 sample.sayNick("genious");이 수행이 된다.

하지만 main 메서드에서 예외 처리를 한 경우에는 두번 째 문장인 `sample.sayNick("genious");`가 수행되지 않는다.  
이미 첫번 째 문장에서 예외가 발생하여 catch 문으로 빠져버리기 때문이다.

ㅤ
ㅤ

ㅤ

ㅤ

ㅤ

ㅤ

## 5. 트랜잭션 (Transaction)

트랜잭션은 하나의 작업 단위를 뜻한다.

메서드에서는 예외를 throw하고 다른 메서드에서 throw된 예외를 처리하여 모두 취소하는 것이 완벽한 트랜잭션 처리 방법이다.

ex:

```jsva
상품발송() {
    try {
        포장();
        영수증발행();
        발송();
    }catch(예외) {
        모두취소();  // 하나라도 실패하면 모두 취소한다.
    }
}

포장() throws 예외 {
   ...
}

영수증발행() throws 예외 {
   ...
}

발송() throws 예외 {
   ...
}
```

위와 같이 코드를 작성하면 포장, 영수증발행, 발송이라는 세개의 단위작업 중 하나라도 실패할 경우 "예외"가 발생되어 상품발송이 모두 취소 될 것이다.
